2022-02-09 12:53:07,880 - WARNING - info_parser.py[:24] - cookie错误或已过期,请按照README中方法重新获取
2022-02-09 13:06:10,948 - ERROR - downloader.py[:49] - HTTPConnectionPool(host='ww4.sinaimg.cn', port=80): Max retries exceeded with url: /large/6e98b571gy1gz3w8lrzi4j20u016yn5k.jpg (Caused by NewConnectionError('<urllib3.connection.HTTPConnection object at 0x0000024736F5B448>: Failed to establish a new connection: [Errno 11001] getaddrinfo failed'))
Traceback (most recent call last):
  File "E:\ana\envs\otk\lib\site-packages\urllib3\connection.py", line 175, in _new_conn
    (self._dns_host, self.port), self.timeout, **extra_kw
  File "E:\ana\envs\otk\lib\site-packages\urllib3\util\connection.py", line 72, in create_connection
    for res in socket.getaddrinfo(host, port, family, socket.SOCK_STREAM):
  File "E:\ana\envs\otk\lib\socket.py", line 752, in getaddrinfo
    for res in _socket.getaddrinfo(host, port, family, type, proto, flags):
socket.gaierror: [Errno 11001] getaddrinfo failed

During handling of the above exception, another exception occurred:

Traceback (most recent call last):
  File "E:\ana\envs\otk\lib\site-packages\urllib3\connectionpool.py", line 710, in urlopen
    chunked=chunked,
  File "E:\ana\envs\otk\lib\site-packages\urllib3\connectionpool.py", line 398, in _make_request
    conn.request(method, url, **httplib_request_kw)
  File "E:\ana\envs\otk\lib\site-packages\urllib3\connection.py", line 239, in request
    super(HTTPConnection, self).request(method, url, body=body, headers=headers)
  File "E:\ana\envs\otk\lib\http\client.py", line 1281, in request
    self._send_request(method, url, body, headers, encode_chunked)
  File "E:\ana\envs\otk\lib\http\client.py", line 1327, in _send_request
    self.endheaders(body, encode_chunked=encode_chunked)
  File "E:\ana\envs\otk\lib\http\client.py", line 1276, in endheaders
    self._send_output(message_body, encode_chunked=encode_chunked)
  File "E:\ana\envs\otk\lib\http\client.py", line 1036, in _send_output
    self.send(msg)
  File "E:\ana\envs\otk\lib\http\client.py", line 976, in send
    self.connect()
  File "E:\ana\envs\otk\lib\site-packages\urllib3\connection.py", line 205, in connect
    conn = self._new_conn()
  File "E:\ana\envs\otk\lib\site-packages\urllib3\connection.py", line 187, in _new_conn
    self, "Failed to establish a new connection: %s" % e
urllib3.exceptions.NewConnectionError: <urllib3.connection.HTTPConnection object at 0x0000024736F5B448>: Failed to establish a new connection: [Errno 11001] getaddrinfo failed

During handling of the above exception, another exception occurred:

Traceback (most recent call last):
  File "E:\ana\envs\otk\lib\site-packages\requests\adapters.py", line 450, in send
    timeout=timeout
  File "E:\ana\envs\otk\lib\site-packages\urllib3\connectionpool.py", line 826, in urlopen
    **response_kw
  File "E:\ana\envs\otk\lib\site-packages\urllib3\connectionpool.py", line 826, in urlopen
    **response_kw
  File "E:\ana\envs\otk\lib\site-packages\urllib3\connectionpool.py", line 826, in urlopen
    **response_kw
  [Previous line repeated 2 more times]
  File "E:\ana\envs\otk\lib\site-packages\urllib3\connectionpool.py", line 786, in urlopen
    method, url, error=e, _pool=self, _stacktrace=sys.exc_info()[2]
  File "E:\ana\envs\otk\lib\site-packages\urllib3\util\retry.py", line 592, in increment
    raise MaxRetryError(_pool, url, error or ResponseError(cause))
urllib3.exceptions.MaxRetryError: HTTPConnectionPool(host='ww4.sinaimg.cn', port=80): Max retries exceeded with url: /large/6e98b571gy1gz3w8lrzi4j20u016yn5k.jpg (Caused by NewConnectionError('<urllib3.connection.HTTPConnection object at 0x0000024736F5B448>: Failed to establish a new connection: [Errno 11001] getaddrinfo failed'))

During handling of the above exception, another exception occurred:

Traceback (most recent call last):
  File "E:\ana\envs\otk\lib\site-packages\weibo_spider\downloader\downloader.py", line 41, in download_one_file
    self.file_download_timeout[2]))
  File "E:\ana\envs\otk\lib\site-packages\requests\sessions.py", line 542, in get
    return self.request('GET', url, **kwargs)
  File "E:\ana\envs\otk\lib\site-packages\requests\sessions.py", line 529, in request
    resp = self.send(prep, **send_kwargs)
  File "E:\ana\envs\otk\lib\site-packages\requests\sessions.py", line 645, in send
    r = adapter.send(request, **kwargs)
  File "E:\ana\envs\otk\lib\site-packages\requests\adapters.py", line 519, in send
    raise ConnectionError(e, request=request)
requests.exceptions.ConnectionError: HTTPConnectionPool(host='ww4.sinaimg.cn', port=80): Max retries exceeded with url: /large/6e98b571gy1gz3w8lrzi4j20u016yn5k.jpg (Caused by NewConnectionError('<urllib3.connection.HTTPConnection object at 0x0000024736F5B448>: Failed to establish a new connection: [Errno 11001] getaddrinfo failed'))
2022-02-09 14:53:22,148 - ERROR - util.py[:45] - ('Connection aborted.', RemoteDisconnected('Remote end closed connection without response'))
Traceback (most recent call last):
  File "E:\ana\envs\otk\lib\site-packages\urllib3\connectionpool.py", line 710, in urlopen
    chunked=chunked,
  File "E:\ana\envs\otk\lib\site-packages\urllib3\connectionpool.py", line 449, in _make_request
    six.raise_from(e, None)
  File "<string>", line 3, in raise_from
  File "E:\ana\envs\otk\lib\site-packages\urllib3\connectionpool.py", line 444, in _make_request
    httplib_response = conn.getresponse()
  File "E:\ana\envs\otk\lib\http\client.py", line 1373, in getresponse
    response.begin()
  File "E:\ana\envs\otk\lib\http\client.py", line 319, in begin
    version, status, reason = self._read_status()
  File "E:\ana\envs\otk\lib\http\client.py", line 288, in _read_status
    raise RemoteDisconnected("Remote end closed connection without"
http.client.RemoteDisconnected: Remote end closed connection without response

During handling of the above exception, another exception occurred:

Traceback (most recent call last):
  File "E:\ana\envs\otk\lib\site-packages\requests\adapters.py", line 450, in send
    timeout=timeout
  File "E:\ana\envs\otk\lib\site-packages\urllib3\connectionpool.py", line 786, in urlopen
    method, url, error=e, _pool=self, _stacktrace=sys.exc_info()[2]
  File "E:\ana\envs\otk\lib\site-packages\urllib3\util\retry.py", line 550, in increment
    raise six.reraise(type(error), error, _stacktrace)
  File "E:\ana\envs\otk\lib\site-packages\urllib3\packages\six.py", line 769, in reraise
    raise value.with_traceback(tb)
  File "E:\ana\envs\otk\lib\site-packages\urllib3\connectionpool.py", line 710, in urlopen
    chunked=chunked,
  File "E:\ana\envs\otk\lib\site-packages\urllib3\connectionpool.py", line 449, in _make_request
    six.raise_from(e, None)
  File "<string>", line 3, in raise_from
  File "E:\ana\envs\otk\lib\site-packages\urllib3\connectionpool.py", line 444, in _make_request
    httplib_response = conn.getresponse()
  File "E:\ana\envs\otk\lib\http\client.py", line 1373, in getresponse
    response.begin()
  File "E:\ana\envs\otk\lib\http\client.py", line 319, in begin
    version, status, reason = self._read_status()
  File "E:\ana\envs\otk\lib\http\client.py", line 288, in _read_status
    raise RemoteDisconnected("Remote end closed connection without"
urllib3.exceptions.ProtocolError: ('Connection aborted.', RemoteDisconnected('Remote end closed connection without response'))

During handling of the above exception, another exception occurred:

Traceback (most recent call last):
  File "E:\ana\envs\otk\lib\site-packages\weibo_spider\parser\util.py", line 25, in handle_html
    resp = requests.get(url, headers=headers)
  File "E:\ana\envs\otk\lib\site-packages\requests\api.py", line 75, in get
    return request('get', url, params=params, **kwargs)
  File "E:\ana\envs\otk\lib\site-packages\requests\api.py", line 61, in request
    return session.request(method=method, url=url, **kwargs)
  File "E:\ana\envs\otk\lib\site-packages\requests\sessions.py", line 529, in request
    resp = self.send(prep, **send_kwargs)
  File "E:\ana\envs\otk\lib\site-packages\requests\sessions.py", line 645, in send
    r = adapter.send(request, **kwargs)
  File "E:\ana\envs\otk\lib\site-packages\requests\adapters.py", line 501, in send
    raise ConnectionError(err, request=request)
requests.exceptions.ConnectionError: ('Connection aborted.', RemoteDisconnected('Remote end closed connection without response'))
2022-02-09 14:53:44,745 - ERROR - util.py[:45] - HTTPSConnectionPool(host='weibo.cn', port=443): Max retries exceeded with url: /comment/KkggkDBfb (Caused by NewConnectionError('<urllib3.connection.HTTPSConnection object at 0x0000017A2986F508>: Failed to establish a new connection: [WinError 10053] 確立された接続がホスト コンピューターのソウトウェアによって中止されました。'))
Traceback (most recent call last):
  File "E:\ana\envs\otk\lib\site-packages\urllib3\connection.py", line 175, in _new_conn
    (self._dns_host, self.port), self.timeout, **extra_kw
  File "E:\ana\envs\otk\lib\site-packages\urllib3\util\connection.py", line 95, in create_connection
    raise err
  File "E:\ana\envs\otk\lib\site-packages\urllib3\util\connection.py", line 85, in create_connection
    sock.connect(sa)
ConnectionAbortedError: [WinError 10053] 確立された接続がホスト コンピューターのソウトウェアによって中止されました。

During handling of the above exception, another exception occurred:

Traceback (most recent call last):
  File "E:\ana\envs\otk\lib\site-packages\urllib3\connectionpool.py", line 710, in urlopen
    chunked=chunked,
  File "E:\ana\envs\otk\lib\site-packages\urllib3\connectionpool.py", line 386, in _make_request
    self._validate_conn(conn)
  File "E:\ana\envs\otk\lib\site-packages\urllib3\connectionpool.py", line 1040, in _validate_conn
    conn.connect()
  File "E:\ana\envs\otk\lib\site-packages\urllib3\connection.py", line 358, in connect
    conn = self._new_conn()
  File "E:\ana\envs\otk\lib\site-packages\urllib3\connection.py", line 187, in _new_conn
    self, "Failed to establish a new connection: %s" % e
urllib3.exceptions.NewConnectionError: <urllib3.connection.HTTPSConnection object at 0x0000017A2986F508>: Failed to establish a new connection: [WinError 10053] 確立された接続がホスト コンピューターのソウトウェアによって中止されました。

During handling of the above exception, another exception occurred:

Traceback (most recent call last):
  File "E:\ana\envs\otk\lib\site-packages\requests\adapters.py", line 450, in send
    timeout=timeout
  File "E:\ana\envs\otk\lib\site-packages\urllib3\connectionpool.py", line 786, in urlopen
    method, url, error=e, _pool=self, _stacktrace=sys.exc_info()[2]
  File "E:\ana\envs\otk\lib\site-packages\urllib3\util\retry.py", line 592, in increment
    raise MaxRetryError(_pool, url, error or ResponseError(cause))
urllib3.exceptions.MaxRetryError: HTTPSConnectionPool(host='weibo.cn', port=443): Max retries exceeded with url: /comment/KkggkDBfb (Caused by NewConnectionError('<urllib3.connection.HTTPSConnection object at 0x0000017A2986F508>: Failed to establish a new connection: [WinError 10053] 確立された接続がホスト コンピューターのソウトウェアによって中止されました。'))

During handling of the above exception, another exception occurred:

Traceback (most recent call last):
  File "E:\ana\envs\otk\lib\site-packages\weibo_spider\parser\util.py", line 25, in handle_html
    resp = requests.get(url, headers=headers)
  File "E:\ana\envs\otk\lib\site-packages\requests\api.py", line 75, in get
    return request('get', url, params=params, **kwargs)
  File "E:\ana\envs\otk\lib\site-packages\requests\api.py", line 61, in request
    return session.request(method=method, url=url, **kwargs)
  File "E:\ana\envs\otk\lib\site-packages\requests\sessions.py", line 529, in request
    resp = self.send(prep, **send_kwargs)
  File "E:\ana\envs\otk\lib\site-packages\requests\sessions.py", line 645, in send
    r = adapter.send(request, **kwargs)
  File "E:\ana\envs\otk\lib\site-packages\requests\adapters.py", line 519, in send
    raise ConnectionError(e, request=request)
requests.exceptions.ConnectionError: HTTPSConnectionPool(host='weibo.cn', port=443): Max retries exceeded with url: /comment/KkggkDBfb (Caused by NewConnectionError('<urllib3.connection.HTTPSConnection object at 0x0000017A2986F508>: Failed to establish a new connection: [WinError 10053] 確立された接続がホスト コンピューターのソウトウェアによって中止されました。'))
2022-02-09 15:00:16,553 - ERROR - util.py[:45] - HTTPSConnectionPool(host='weibo.cn', port=443): Max retries exceeded with url: /1855501681/profile?page=184 (Caused by NewConnectionError('<urllib3.connection.HTTPSConnection object at 0x0000017A29888588>: Failed to establish a new connection: [Errno 11001] getaddrinfo failed'))
Traceback (most recent call last):
  File "E:\ana\envs\otk\lib\site-packages\urllib3\connection.py", line 175, in _new_conn
    (self._dns_host, self.port), self.timeout, **extra_kw
  File "E:\ana\envs\otk\lib\site-packages\urllib3\util\connection.py", line 72, in create_connection
    for res in socket.getaddrinfo(host, port, family, socket.SOCK_STREAM):
  File "E:\ana\envs\otk\lib\socket.py", line 752, in getaddrinfo
    for res in _socket.getaddrinfo(host, port, family, type, proto, flags):
socket.gaierror: [Errno 11001] getaddrinfo failed

During handling of the above exception, another exception occurred:

Traceback (most recent call last):
  File "E:\ana\envs\otk\lib\site-packages\urllib3\connectionpool.py", line 710, in urlopen
    chunked=chunked,
  File "E:\ana\envs\otk\lib\site-packages\urllib3\connectionpool.py", line 386, in _make_request
    self._validate_conn(conn)
  File "E:\ana\envs\otk\lib\site-packages\urllib3\connectionpool.py", line 1040, in _validate_conn
    conn.connect()
  File "E:\ana\envs\otk\lib\site-packages\urllib3\connection.py", line 358, in connect
    conn = self._new_conn()
  File "E:\ana\envs\otk\lib\site-packages\urllib3\connection.py", line 187, in _new_conn
    self, "Failed to establish a new connection: %s" % e
urllib3.exceptions.NewConnectionError: <urllib3.connection.HTTPSConnection object at 0x0000017A29888588>: Failed to establish a new connection: [Errno 11001] getaddrinfo failed

During handling of the above exception, another exception occurred:

Traceback (most recent call last):
  File "E:\ana\envs\otk\lib\site-packages\requests\adapters.py", line 450, in send
    timeout=timeout
  File "E:\ana\envs\otk\lib\site-packages\urllib3\connectionpool.py", line 786, in urlopen
    method, url, error=e, _pool=self, _stacktrace=sys.exc_info()[2]
  File "E:\ana\envs\otk\lib\site-packages\urllib3\util\retry.py", line 592, in increment
    raise MaxRetryError(_pool, url, error or ResponseError(cause))
urllib3.exceptions.MaxRetryError: HTTPSConnectionPool(host='weibo.cn', port=443): Max retries exceeded with url: /1855501681/profile?page=184 (Caused by NewConnectionError('<urllib3.connection.HTTPSConnection object at 0x0000017A29888588>: Failed to establish a new connection: [Errno 11001] getaddrinfo failed'))

During handling of the above exception, another exception occurred:

Traceback (most recent call last):
  File "E:\ana\envs\otk\lib\site-packages\weibo_spider\parser\util.py", line 25, in handle_html
    resp = requests.get(url, headers=headers)
  File "E:\ana\envs\otk\lib\site-packages\requests\api.py", line 75, in get
    return request('get', url, params=params, **kwargs)
  File "E:\ana\envs\otk\lib\site-packages\requests\api.py", line 61, in request
    return session.request(method=method, url=url, **kwargs)
  File "E:\ana\envs\otk\lib\site-packages\requests\sessions.py", line 529, in request
    resp = self.send(prep, **send_kwargs)
  File "E:\ana\envs\otk\lib\site-packages\requests\sessions.py", line 645, in send
    r = adapter.send(request, **kwargs)
  File "E:\ana\envs\otk\lib\site-packages\requests\adapters.py", line 519, in send
    raise ConnectionError(e, request=request)
requests.exceptions.ConnectionError: HTTPSConnectionPool(host='weibo.cn', port=443): Max retries exceeded with url: /1855501681/profile?page=184 (Caused by NewConnectionError('<urllib3.connection.HTTPSConnection object at 0x0000017A29888588>: Failed to establish a new connection: [Errno 11001] getaddrinfo failed'))
2022-02-09 15:00:16,560 - ERROR - spider.py[:221] - 'NoneType' object has no attribute 'xpath'
Traceback (most recent call last):
  File "E:\ana\envs\otk\lib\site-packages\weibo_spider\spider.py", line 180, in get_weibo_info
    self.user_config, page, self.filter).get_one_page(
  File "E:\ana\envs\otk\lib\site-packages\weibo_spider\parser\page_parser.py", line 47, in __init__
    info = self.selector.xpath("//div[@class='c']")
AttributeError: 'NoneType' object has no attribute 'xpath'
2022-02-09 15:16:42,728 - ERROR - util.py[:45] - HTTPSConnectionPool(host='weibo.cn', port=443): Max retries exceeded with url: /mblog/picAll/JBVrTp9FL?rl=1 (Caused by NewConnectionError('<urllib3.connection.HTTPSConnection object at 0x000001C8A7B61B48>: Failed to establish a new connection: [Errno 11001] getaddrinfo failed'))
Traceback (most recent call last):
  File "E:\ana\envs\otk\lib\site-packages\urllib3\connection.py", line 175, in _new_conn
    (self._dns_host, self.port), self.timeout, **extra_kw
  File "E:\ana\envs\otk\lib\site-packages\urllib3\util\connection.py", line 72, in create_connection
    for res in socket.getaddrinfo(host, port, family, socket.SOCK_STREAM):
  File "E:\ana\envs\otk\lib\socket.py", line 752, in getaddrinfo
    for res in _socket.getaddrinfo(host, port, family, type, proto, flags):
socket.gaierror: [Errno 11001] getaddrinfo failed

During handling of the above exception, another exception occurred:

Traceback (most recent call last):
  File "E:\ana\envs\otk\lib\site-packages\urllib3\connectionpool.py", line 710, in urlopen
    chunked=chunked,
  File "E:\ana\envs\otk\lib\site-packages\urllib3\connectionpool.py", line 386, in _make_request
    self._validate_conn(conn)
  File "E:\ana\envs\otk\lib\site-packages\urllib3\connectionpool.py", line 1040, in _validate_conn
    conn.connect()
  File "E:\ana\envs\otk\lib\site-packages\urllib3\connection.py", line 358, in connect
    conn = self._new_conn()
  File "E:\ana\envs\otk\lib\site-packages\urllib3\connection.py", line 187, in _new_conn
    self, "Failed to establish a new connection: %s" % e
urllib3.exceptions.NewConnectionError: <urllib3.connection.HTTPSConnection object at 0x000001C8A7B61B48>: Failed to establish a new connection: [Errno 11001] getaddrinfo failed

During handling of the above exception, another exception occurred:

Traceback (most recent call last):
  File "E:\ana\envs\otk\lib\site-packages\requests\adapters.py", line 450, in send
    timeout=timeout
  File "E:\ana\envs\otk\lib\site-packages\urllib3\connectionpool.py", line 786, in urlopen
    method, url, error=e, _pool=self, _stacktrace=sys.exc_info()[2]
  File "E:\ana\envs\otk\lib\site-packages\urllib3\util\retry.py", line 592, in increment
    raise MaxRetryError(_pool, url, error or ResponseError(cause))
urllib3.exceptions.MaxRetryError: HTTPSConnectionPool(host='weibo.cn', port=443): Max retries exceeded with url: /mblog/picAll/JBVrTp9FL?rl=1 (Caused by NewConnectionError('<urllib3.connection.HTTPSConnection object at 0x000001C8A7B61B48>: Failed to establish a new connection: [Errno 11001] getaddrinfo failed'))

During handling of the above exception, another exception occurred:

Traceback (most recent call last):
  File "E:\ana\envs\otk\lib\site-packages\weibo_spider\parser\util.py", line 25, in handle_html
    resp = requests.get(url, headers=headers)
  File "E:\ana\envs\otk\lib\site-packages\requests\api.py", line 75, in get
    return request('get', url, params=params, **kwargs)
  File "E:\ana\envs\otk\lib\site-packages\requests\api.py", line 61, in request
    return session.request(method=method, url=url, **kwargs)
  File "E:\ana\envs\otk\lib\site-packages\requests\sessions.py", line 529, in request
    resp = self.send(prep, **send_kwargs)
  File "E:\ana\envs\otk\lib\site-packages\requests\sessions.py", line 645, in send
    r = adapter.send(request, **kwargs)
  File "E:\ana\envs\otk\lib\site-packages\requests\adapters.py", line 519, in send
    raise ConnectionError(e, request=request)
requests.exceptions.ConnectionError: HTTPSConnectionPool(host='weibo.cn', port=443): Max retries exceeded with url: /mblog/picAll/JBVrTp9FL?rl=1 (Caused by NewConnectionError('<urllib3.connection.HTTPSConnection object at 0x000001C8A7B61B48>: Failed to establish a new connection: [Errno 11001] getaddrinfo failed'))
2022-02-09 15:16:42,735 - ERROR - page_parser.py[:379] - 'NoneType' object has no attribute 'xpath'
Traceback (most recent call last):
  File "E:\ana\envs\otk\lib\site-packages\weibo_spider\parser\page_parser.py", line 354, in extract_picture_urls
    self.cookie, weibo_id).extract_preview_picture_list()
  File "E:\ana\envs\otk\lib\site-packages\weibo_spider\parser\mblog_picAll_parser.py", line 12, in extract_preview_picture_list
    return self.selector.xpath('//img/@src')
AttributeError: 'NoneType' object has no attribute 'xpath'
